<mujoco model="HU_D04">
  <compiler angle="radian" meshdir="../meshes/"/>

  <asset>
    <mesh name="base_link" content_type="model/stl" file="HU_D04_01/base_link.STL"/>
    <mesh name="left_hip_pitch_link" content_type="model/stl" file="HU_D04_01/left_hip_pitch_link.STL"/>
    <mesh name="left_hip_roll_link" content_type="model/stl" file="HU_D04_01/left_hip_roll_link.STL"/>
    <mesh name="left_hip_yaw_link" content_type="model/stl" file="HU_D04_01/left_hip_yaw_link.STL"/>
    <mesh name="left_knee_link" content_type="model/stl" file="HU_D04_01/left_knee_link.STL"/>
    <mesh name="left_ankle_pitch_link" content_type="model/stl" file="HU_D04_01/left_ankle_pitch_link.STL"/>
    <mesh name="left_ankle_roll_link" content_type="model/stl" file="HU_D04_01/left_ankle_roll_link.STL"/>
    <mesh name="right_hip_pitch_link" content_type="model/stl" file="HU_D04_01/right_hip_pitch_link.STL"/>
    <mesh name="right_hip_roll_link" content_type="model/stl" file="HU_D04_01/right_hip_roll_link.STL"/>
    <mesh name="right_hip_yaw_link" content_type="model/stl" file="HU_D04_01/right_hip_yaw_link.STL"/>
    <mesh name="right_knee_link" content_type="model/stl" file="HU_D04_01/right_knee_link.STL"/>
    <mesh name="right_ankle_pitch_link" content_type="model/stl" file="HU_D04_01/right_ankle_pitch_link.STL"/>
    <mesh name="right_ankle_roll_link" content_type="model/stl" file="HU_D04_01/right_ankle_roll_link.STL"/>
    <mesh name="waist_yaw_link" content_type="model/stl" file="HU_D04_01/waist_yaw_link.STL"/>
    <mesh name="waist_roll_link" content_type="model/stl" file="HU_D04_01/waist_roll_link.STL"/>
    <mesh name="waist_pitch_link" content_type="model/stl" file="HU_D04_01/waist_pitch_link.STL"/>
    <mesh name="head_yaw_link" content_type="model/stl" file="HU_D04_01/neck_yaw_link.STL"/>
    <mesh name="head_pitch_link" content_type="model/stl" file="HU_D04_01/neck_pitch_link.STL"/>
    <mesh name="left_shoulder_pitch_link" content_type="model/stl" file="HU_D04_01/left_shoulder_pitch_link.STL"/>
    <mesh name="left_shoulder_roll_link" content_type="model/stl" file="HU_D04_01/left_shoulder_roll_link.STL"/>
    <mesh name="left_shoulder_yaw_link" content_type="model/stl" file="HU_D04_01/left_shoulder_yaw_link.STL"/>
    <mesh name="left_elbow_link" content_type="model/stl" file="HU_D04_01/left_elbow_link.STL"/>
    <mesh name="left_wrist_yaw_link" content_type="model/stl" file="HU_D04_01/left_wrist_yaw_link.STL"/>
    <mesh name="left_wrist_pitch_link" content_type="model/stl" file="HU_D04_01/left_wrist_pitch_link.STL"/>
    <mesh name="left_wrist_roll_link" content_type="model/stl" file="HU_D04_01/left_wrist_roll_link.STL"/>
    <mesh name="right_shoulder_pitch_link" content_type="model/stl" file="HU_D04_01/right_shoulder_pitch_link.STL"/>
    <mesh name="right_shoulder_roll_link" content_type="model/stl" file="HU_D04_01/right_shoulder_roll_link.STL"/>
    <mesh name="right_shoulder_yaw_link" content_type="model/stl" file="HU_D04_01/right_shoulder_yaw_link.STL"/>
    <mesh name="right_elbow_link" content_type="model/stl" file="HU_D04_01/right_elbow_link.STL"/>
    <mesh name="right_wrist_yaw_link" content_type="model/stl" file="HU_D04_01/right_wrist_yaw_link.STL"/>
    <mesh name="right_wrist_pitch_link" content_type="model/stl" file="HU_D04_01/right_wrist_pitch_link.STL"/>
    <mesh name="right_wrist_roll_link" content_type="model/stl" file="HU_D04_01/right_wrist_roll_link.STL"/>
  </asset>

  <worldbody>
    <body name="base_link" pos="0 0 1.0">
      <site name="imu" size="0.01" pos="0.0 0.0 0.0"/>
      <inertial pos="0.002916 -8e-06 0.041359" quat="0.612805 0.613066 -0.352574 0.352579" mass="5.904962" diaginertia="0.040472 0.038209 0.013916"/>
      <joint name="floating_base_joint" type="free" limited="false" actuatorfrclimited="false"/>
      <geom type="mesh" contype="0" conaffinity="0" group="1" density="0" rgba="0.75294 0.75294 0.75294 1" mesh="base_link"/>
      <geom pos="-0.06 0 0.055" size="0.047 0.04" type="cylinder" rgba="0.7 0.7 0.7 0.5"/>
      <geom pos="0.015 0.08 0.028" euler="1.15 0 0" size="0.055 0.03" type="cylinder" rgba="0.7 0.7 0.7 0.5"/>
      <geom pos="0.015 -0.08 0.028" euler="-1.15 0 0" size="0.055 0.03" type="cylinder" rgba="0.7 0.7 0.7 0.5"/>

      <!-- left leg -->
      <body name="left_hip_pitch_link" pos="0.017007 0.1283 0.0081917">
        <inertial pos="0.0019 0.001536 -0.086008" quat="0.707518 0.0266383 1.73517e-05 0.706193" mass="2.255011" diaginertia="0.003816 0.003233 0.002888"/>
        <joint name="left_hip_pitch_joint" pos="0 0 0" axis="0 0.90631 -0.42262" range="-2.618 2.618" armature="0.14125"/>
        <geom type="mesh" contype="0" conaffinity="0" group="1" density="0" rgba="0.75294 0.75294 0.75294 1" mesh="left_hip_pitch_link"/>
        <geom type="cylinder" pos="-0.0107 0.0012 -0.0916" size="0.05 0.06" euler="0 1.57 0" rgba="0.7 0.7 0.7 0.5"/>
        <body name="left_hip_roll_link" pos="-0.01 0.0016596 -0.0920417">
          <inertial pos="0.00075 1e-05 -0.118609" quat="0.711183 0.0283968 0.0283187 0.701862" mass="2.121806" diaginertia="0.004267 0.004035 0.002342"/>
          <joint name="left_hip_roll_joint" pos="0 0 0" axis="1 0 0" range="-0.8727 2.094" armature="0.14125"/>
          <geom type="mesh" contype="0" conaffinity="0" group="1" density="0" rgba="0.75294 0.75294 0.75294 1" mesh="left_hip_roll_link"/>
          <body name="left_hip_yaw_link" pos="0 0 -0.1774">
            <inertial pos="0.006364 0.000963 -0.143266" quat="0.708658 0.0234255 0.019567 0.704891" mass="2.994098" diaginertia="0.024609 0.024104 0.004856"/>
            <joint name="left_hip_yaw_joint" pos="0 0 0" axis="0 0 1" range="-2.618 2.618" armature="0.14125"/>
            <geom type="mesh" contype="0" conaffinity="0" group="1" density="0" rgba="0.75294 0.75294 0.75294 1" mesh="left_hip_yaw_link"/>
            <geom type="capsule" pos="0.015 0.0 -0.0331" size="0.05 0.1" euler="0 -0.1 0" rgba="0.7 0.7 0.7 0.5"/>
            <body name="left_knee_link" pos="0 0 -0.1976">
              <inertial pos="0.008034 0.005502 -0.139341" quat="0.984847 -0.0450884 0.00573951 0.167362" mass="3.004275" diaginertia="0.026945 0.026541 0.003135"/>
              <joint name="left_knee_joint" pos="0 0 0" axis="0 1 0" range="-0.087 2.583" armature="0.14125"/>
              <geom type="mesh" contype="0" conaffinity="0" group="1" density="0" rgba="0.75294 0.75294 0.75294 1" mesh="left_knee_link"/>
              <geom type="capsule" pos="0.015 0.0 -0.2" size="0.035 0.14" euler="0 0.1 0" rgba="0.7 0.7 0.7 0.5"/>
              <body name="left_ankle_pitch_link" pos="0 0 -0.385">
                <inertial pos="0 0 0.001077" quat="0.707107 0.707107 0 0" mass="0.042944" diaginertia="4e-06 4e-06 2e-06"/>
                <joint name="left_ankle_pitch_joint" pos="0 0 0" axis="0 1 0" range="-1.012 0.611" armature="0.1845504"/>
                <geom type="mesh" contype="0" conaffinity="0" group="1" density="0" rgba="0.75294 0.75294 0.75294 1" mesh="left_ankle_pitch_link"/>
                <body name="left_ankle_roll_link" pos="0 0 0">
                  <inertial pos="0.00972 0 -0.035233" quat="0 0.746533 0 0.665348" mass="1.206425" diaginertia="0.00492 0.00476 0.000924"/>
                  <joint name="left_ankle_roll_joint" pos="0 0 0" axis="1 0 0" range="-0.436 0.436" armature="0.1845504"/>
                  <geom type="mesh" contype="0" conaffinity="0" group="1" density="0" rgba="0.75294 0.75294 0.75294 1" mesh="left_ankle_roll_link"/>
                  <geom name="left_foot" pos="0.018 0 -0.0535" size="0.13 0.047 0.01" type="box" rgba="0 0.4 0 0.1"/>
                </body>
              </body>
            </body>
          </body>
        </body>
      </body>

      <!-- right leg -->
      <body name="right_hip_pitch_link" pos="0.017007 -0.1283 0.0081917">
        <inertial pos="0.0019 -0.001536 -0.086008" quat="0.696037 0.0116018 0.0132278 0.71779" mass="2.253993" diaginertia="0.003814 0.003231 0.002888"/>
        <joint name="right_hip_pitch_joint" pos="0 0 0" axis="0 0.90631 0.42262" range="-2.618 2.618" armature="0.14125"/>
        <geom type="mesh" contype="0" conaffinity="0" group="1" density="0" rgba="0.75294 0.75294 0.75294 1" mesh="right_hip_pitch_link"/>
        <geom type="cylinder" pos="-0.0107 -0.0012 -0.0916" size="0.05 0.06" euler="0 1.57 0" rgba="0.7 0.7 0.7 0.5"/>
        <body name="right_hip_roll_link" pos="-0.01 -0.0016596 -0.0920417">
          <inertial pos="0.000764 1e-05 -0.118627" quat="0.711191 0.0288338 0.0287616 0.701819" mass="2.121322" diaginertia="0.004262 0.004031 0.00234"/>
          <joint name="right_hip_roll_joint" pos="0 0 0" axis="1 0 0" range="-2.094 0.8727" armature="0.14125"/>
          <geom type="mesh" contype="0" conaffinity="0" group="1" density="0" rgba="0.75294 0.75294 0.75294 1" mesh="right_hip_roll_link"/>
          <body name="right_hip_yaw_link" pos="0 0 -0.1774">
            <inertial pos="0.006367 -0.000835 -0.143269" quat="0.708337 0.0184695 0.0244582 0.705209" mass="2.994098" diaginertia="0.024611 0.024104 0.004856"/>
            <joint name="right_hip_yaw_joint" pos="0 0 0" axis="0 0 1" range="-2.618 2.618" armature="0.14125"/>
            <geom type="mesh" contype="0" conaffinity="0" group="1" density="0" rgba="0.75294 0.75294 0.75294 1" mesh="right_hip_yaw_link"/>
            <geom type="capsule" pos="0.015 0.0 -0.0331" size="0.05 0.1" euler="0 -0.1 0" rgba="0.7 0.7 0.7 0.5"/>
            <body name="right_knee_link" pos="0 0 -0.1976">
              <inertial pos="0.007541 -0.00542 -0.140219" quat="0.988965 0.0454873 0.0038737 -0.14094" mass="2.944928" diaginertia="0.026634 0.026187 0.00303"/>
              <joint name="right_knee_joint" pos="0 0 0" axis="0 1 0" range="-0.087 2.583" armature="0.14125"/>
              <geom type="mesh" contype="0" conaffinity="0" group="1" density="0" rgba="0.75294 0.75294 0.75294 1" mesh="right_knee_link"/>
              <geom type="capsule" pos="0.015 0.0 -0.2" size="0.035 0.14" euler="0 0.1 0" rgba="0.7 0.7 0.7 0.5"/>
              <body name="right_ankle_pitch_link" pos="0 0 -0.385">
                <inertial pos="0 0 0.001077" quat="0.707107 0.707107 0 0" mass="0.042944" diaginertia="4e-06 4e-06 2e-06"/>
                <joint name="right_ankle_pitch_joint" pos="0 0 0" axis="0 1 0" range="-1.012 0.611" armature="0.1845504"/>
                <geom type="mesh" contype="0" conaffinity="0" group="1" density="0" rgba="0.75294 0.75294 0.75294 1" mesh="right_ankle_pitch_link"/>
                <body name="right_ankle_roll_link" pos="0 0 0">
                  <inertial pos="0.00972 0 -0.035233" quat="0 0.746533 0 0.665348" mass="1.206425" diaginertia="0.00492 0.00476 0.000924"/>
                  <joint name="right_ankle_roll_joint" pos="0 0 0" axis="1 0 0" range="-0.436 0.436" armature="0.1845504"/>
                  <geom type="mesh" contype="0" conaffinity="0" group="1" density="0" rgba="0.75294 0.75294 0.75294 1" mesh="right_ankle_roll_link"/>
                  <geom name="right_foot" pos="0.018 0 -0.0535" size="0.13 0.047 0.01" type="box" rgba="0 0.4 0 0.1"/>
                </body>
              </body>
            </body>
          </body>
        </body>
      </body>

      <!-- waist -->
      <body name="waist_yaw_link" pos="0 0 0.10239">
        <inertial pos="0.019885 -0.000163 0.029632" quat="0.00532361 0.693156 0.0120982 0.720666" mass="0.654749" diaginertia="0.001156 0.001108 0.000616"/>
        <joint name="waist_yaw_joint" pos="0 0 0" axis="0 0 1" range="-2.618 2.618" armature="0.1845504"/>
        <geom type="mesh" contype="0" conaffinity="0" group="1" density="0" rgba="0.75294 0.75294 0.75294 1" mesh="waist_yaw_link"/>
        <body name="waist_roll_link" pos="0 0 0.057">
          <inertial pos="0 0 -0.000149" quat="0.5 0.5 -0.5 0.5" mass="0.291501" diaginertia="0.000164 0.00016 3.6e-05"/>
          <joint name="waist_roll_joint" pos="0 0 0" axis="1 0 0" range="-0.524 0.524" armature="0.1845504"/>
          <geom type="mesh" contype="0" conaffinity="0" group="1" density="0" rgba="0.75294 0.75294 0.75294 1" mesh="waist_roll_link"/>

          <!-- upper body (torso) -->
          <body name="waist_pitch_link" pos="0 0 0">
            <inertial pos="-0.006815 3.8e-05 0.196229" quat="0.999972 -0.000918 -0.007354 0.000965" mass="11.882244" diaginertia="0.169231 0.136241 0.104458"/>
            <joint name="waist_pitch_joint" pos="0 0 0" axis="0 1 0" range="-0.524 0.785" armature="0.1845504"/>
            <geom type="mesh" contype="0" conaffinity="0" group="1" density="0" rgba="0.75294 0.75294 0.75294 1" mesh="waist_pitch_link"/>
            <geom type="capsule" pos="-0.006 0 0.25681" size="0.11 0.055" euler="1.57 0 0" rgba="0.7 0.7 0.7 0.5"/>
            <geom type="capsule" pos="-0.03 0 0.07" size="0.06 0.06" euler="1.57 0 0" rgba="0.7 0.7 0.7 0.5"/>

            <!-- head -->
            <body name="head_yaw_link" pos="-0.013 0 0.3882">
              <inertial pos="-7e-05 0.002132 0.037884" quat="0.990388 0.0534065 -0.0629858 0.110957" mass="0.35819" diaginertia="0.000163 0.000162 0.000146"/>
              <joint name="head_yaw_joint" pos="0 0 0" axis="0 0 1" range="-0.785 0.785" armature="0.0153218"/>
              <geom type="mesh" contype="0" conaffinity="0" group="1" density="0" rgba="0.75294 0.75294 0.75294 1" mesh="head_yaw_link"/>
              <body name="head_pitch_link" pos="0 0 0.0395">
                <inertial pos="0.010255 -0.000319 0.069397" quat="0.552937 0.549111 -0.444832 0.441432" mass="0.776041" diaginertia="0.003495 0.00265 0.002337"/>
                <joint name="head_pitch_joint" pos="0 0 0" axis="0 1 0" range="-0.524 0.785" armature="0.0153218"/>
                <geom type="mesh" contype="0" conaffinity="0" group="1" density="0" rgba="0.75294 0.75294 0.75294 1" mesh="head_pitch_link"/>
                <geom type="box" pos="0.0077 0 0.072" size="0.05 0.075 0.04" euler="0 0.17 0" rgba="0.7 0.7 0.7 0.5"/>
              </body>
            </body>

            <!-- left arm -->
            <body name="left_shoulder_pitch_link" pos="0 0.1589 0.2822">
              <inertial pos="0.003151 0.031104 -2.2e-05" quat="-0.0676949 0.703859 0.0676949 0.703859" mass="0.244765" diaginertia="0.000429 0.000367 0.000253"/>
              <joint name="left_shoulder_pitch_joint" pos="0 0 0" axis="0 1 0" range="-2.792 2.792" armature="0.0886706"/>
              <geom type="mesh" contype="0" conaffinity="0" group="1" density="0" rgba="0.75294 0.75294 0.75294 1" mesh="left_shoulder_pitch_link"/>
              <body name="left_shoulder_roll_link" pos="0 0.055 0">
                <inertial pos="0.003525 8.8e-05 -0.046695" quat="0.999352 0.000207 0.035938 -0.002028" mass="1.740745" diaginertia="0.004948 0.004931 0.001384"/>
                <joint name="left_shoulder_roll_joint" pos="0 0 0" axis="1 0 0" range="-0.087 3.229" armature="0.0886706"/>
                <geom type="mesh" contype="0" conaffinity="0" group="1" density="0" rgba="0.75294 0.75294 0.75294 1" mesh="left_shoulder_roll_link"/>
                <geom type="cylinder" pos="0 0 0" size="0.04 0.038" euler="0 1.57 0" rgba="0.7 0.7 0.7 0.5"/>
                <geom type="cylinder" pos="0 0 -0.082" size="0.04 0.035" rgba="0.7 0.7 0.7 0.5"/>
                <body name="left_shoulder_yaw_link" pos="0 0 -0.1306">
                  <inertial pos="-0.010067 0.003571 -0.065207" quat="0.997939 0.0490395 0.020919 -0.0357061" mass="0.307657" diaginertia="0.000874 0.000738 0.000405"/>
                  <joint name="left_shoulder_yaw_joint" pos="0 0 0" axis="0 0 1" range="-3.403 1.571" armature="0.0886706"/>
                  <geom type="mesh" contype="0" conaffinity="0" group="1" density="0" rgba="0.75294 0.75294 0.75294 1" mesh="left_shoulder_yaw_link"/>
                  <body name="left_elbow_link" pos="0 0 -0.1157">
                    <inertial pos="5.7e-05 0.004497 -0.027441" quat="0.66133 -0.024528 0.021366 0.74939" mass="1.275459" diaginertia="0.002876 0.002852 0.000888"/>
                    <joint name="left_elbow_joint" pos="0 0 0" axis="0 1 0" range="-2.443 1.571" armature="0.0886706"/>
                    <geom type="mesh" contype="0" conaffinity="0" group="1" density="0" rgba="0.75294 0.75294 0.75294 1" mesh="left_elbow_link"/>
                    <geom type="cylinder" pos="0 0 0" size="0.0425 0.04" euler="1.57 0 0" rgba="0.7 0.7 0.7 0.5"/>
                    <geom type="cylinder" pos="0 0 -0.082" size="0.0375 0.025" rgba="0.7 0.7 0.7 0.5"/>
                    <body name="left_wrist_yaw_link" pos="0 0.001 -0.1188">
                      <inertial pos="-0.00242 0.000421 -0.01484" quat="0.713389 0.700768 0 0" mass="0.132906" diaginertia="0.000145 0.000142 8.6e-05"/>
                      <joint name="left_wrist_yaw_joint" pos="0 0 0" axis="0 0 1" range="-2.356 0.785" armature="0.0153218"/>
                      <geom type="mesh" contype="0" conaffinity="0" group="1" density="0" rgba="0.75294 0.75294 0.75294 1" mesh="left_wrist_yaw_link"/>
                      <body name="left_wrist_pitch_link" pos="0 0 -0.0342">
                        <inertial pos="0.001436 0.001303 -0.032233" quat="0.706358 -0.027738 -0.002337 0.707308" mass="0.658602" diaginertia="0.000963 0.000952 0.000296"/>
                        <joint name="left_wrist_pitch_joint" pos="0 0 0" axis="0 1 0" range="-1.571 1.571" armature="0.0153218"/>
                        <geom type="mesh" contype="0" conaffinity="0" group="1" density="0" rgba="0.75294 0.75294 0.75294 1" mesh="left_wrist_pitch_link"/>
                        <body name="left_wrist_roll_link" pos="0 0 -0.065">
                          <inertial pos="0.004695 -0.002046 -0.088776" quat="0.763155 -0.029446 0.001055 0.645543" mass="0.581445" diaginertia="0.002273 0.002124 0.000445"/>
                          <joint name="left_wrist_roll_joint" pos="0 0 0" axis="1 0 0" range="-1.571 1.571" armature="0.0153218"/>
                          <geom type="mesh" contype="0" conaffinity="0" group="1" density="0" rgba="0.75294 0.75294 0.75294 1" mesh="left_wrist_roll_link"/>
                          <geom type="mesh" rgba="0.75294 0.75294 0.75294 1" mesh="left_wrist_roll_link"/>
                        </body>
                      </body>
                    </body>
                  </body>
                </body>
              </body>
            </body>

            <!-- right arm -->
            <body name="right_shoulder_pitch_link" pos="0 -0.1589 0.2822">
              <inertial pos="0.003151 -0.031104 -2.2e-05" quat="0.0676949 0.703859 -0.0676949 0.703859" mass="0.244765" diaginertia="0.000429 0.000367 0.000253"/>
              <joint name="right_shoulder_pitch_joint" pos="0 0 0" axis="0 1 0" range="-2.792 2.792" armature="0.0886706"/>
              <geom type="mesh" contype="0" conaffinity="0" group="1" density="0" rgba="0.75294 0.75294 0.75294 1" mesh="right_shoulder_pitch_link"/>
              <body name="right_shoulder_roll_link" pos="0 -0.055 0">
                <inertial pos="0.003553 8e-05 -0.046159" quat="0.998961 0.001167 0.036127 0.027744" mass="1.727406" diaginertia="0.00488 0.004864 0.001378"/>
                <joint name="right_shoulder_roll_joint" pos="0 0 0" axis="1 0 0" range="-3.229 0.087" armature="0.0886706"/>
                <geom type="mesh" contype="0" conaffinity="0" group="1" density="0" rgba="0.75294 0.75294 0.75294 1" mesh="right_shoulder_roll_link"/>
                <geom type="cylinder" pos="0 0 0" size="0.04 0.038" euler="0 1.57 0" rgba="0.7 0.7 0.7 0.5"/>
                <geom type="cylinder" pos="0 0 -0.082" size="0.04 0.035" rgba="0.7 0.7 0.7 0.5"/>
                <body name="right_shoulder_yaw_link" pos="0 0 -0.1306">
                  <inertial pos="-0.009999 -0.003523 -0.06579" quat="0.997439 -0.054928 0.021251 0.040591" mass="0.306436" diaginertia="0.000871 0.000736 0.000405"/>
                  <joint name="right_shoulder_yaw_joint" pos="0 0 0" axis="0 0 1" range="-1.571 3.403" armature="0.0886706"/>
                  <geom type="mesh" contype="0" conaffinity="0" group="1" density="0" rgba="0.75294 0.75294 0.75294 1" mesh="right_shoulder_yaw_link"/>
                  <body name="right_elbow_link" pos="0 0 -0.1157">
                    <inertial pos="5.7e-05 -0.004497 -0.027441" quat="0.74939 0.021366 -0.024528 0.66133" mass="1.275459" diaginertia="0.002876 0.002852 0.000888"/>
                    <joint name="right_elbow_joint" pos="0 0 0" axis="0 1 0" range="-2.443 1.571" armature="0.0886706"/>
                    <geom type="mesh" contype="0" conaffinity="0" group="1" density="0" rgba="0.75294 0.75294 0.75294 1" mesh="right_elbow_link"/>
                    <geom type="cylinder" pos="0 0 0" size="0.0425 0.04" euler="1.57 0 0" rgba="0.7 0.7 0.7 0.5"/>
                    <geom type="cylinder" pos="0 0 -0.082" size="0.0375 0.025" rgba="0.7 0.7 0.7 0.5"/>
                    <body name="right_wrist_yaw_link" pos="0 -0.001 -0.1188">
                      <inertial pos="-0.00242 -0.000421 -0.01484" quat="0.700768 0.713389 0 0" mass="0.132906" diaginertia="0.000145 0.000142 8.6e-05"/>
                      <joint name="right_wrist_yaw_joint" pos="0 0 0" axis="0 0 1" range="-0.785 2.356" armature="0.0153218"/>
                      <geom type="mesh" contype="0" conaffinity="0" group="1" density="0" rgba="0.75294 0.75294 0.75294 1" mesh="right_wrist_yaw_link"/>
                      <body name="right_wrist_pitch_link" pos="0 0 -0.0342">
                        <inertial pos="0.001436 -0.001303 -0.032233" quat="0.707308 -0.002337 -0.027738 0.706358" mass="0.658602" diaginertia="0.000963 0.000952 0.000296"/>
                        <joint name="right_wrist_pitch_joint" pos="0 0 0" axis="0 1 0" range="-1.571 1.571" armature="0.0153218"/>
                        <geom type="mesh" contype="0" conaffinity="0" group="1" density="0" rgba="0.75294 0.75294 0.75294 1" mesh="right_wrist_pitch_link"/>
                        <body name="right_wrist_roll_link" pos="0 0 -0.065">
                          <inertial pos="0.004695 0.002046 -0.088776" quat="0.645543 0.001055 -0.029446 0.763155" mass="0.581445" diaginertia="0.002273 0.002124 0.000445"/>
                          <joint name="right_wrist_roll_joint" pos="0 0 0" axis="1 0 0" range="-1.571 1.571" armature="0.0153218"/>
                          <geom type="mesh" contype="0" conaffinity="0" group="1" density="0" rgba="0.75294 0.75294 0.75294 1" mesh="right_wrist_roll_link"/>
                          <geom type="mesh" rgba="0.75294 0.75294 0.75294 1" mesh="right_wrist_roll_link"/>
                        </body>
                      </body>
                    </body>
                  </body>
                </body>
              </body>
            </body>
          </body>
        </body>
      </body>
    </body>
  </worldbody>

  <actuator>
    <!-- Left leg -->
    <motor name="left_hip_pitch" gear="1" joint="left_hip_pitch_joint" ctrllimited="true" ctrlrange="-140 140"/>
    <motor name="left_hip_roll" gear="1" joint="left_hip_roll_joint" ctrllimited="true" ctrlrange="-140 140"/>
    <motor name="left_hip_yaw" gear="1" joint="left_hip_yaw_joint" ctrllimited="true" ctrlrange="-140 140"/>
    <motor name="left_knee" gear="1" joint="left_knee_joint" ctrllimited="true" ctrlrange="-140 140"/>
    <motor name="left_ankle_pitch" gear="1" joint="left_ankle_pitch_joint" ctrllimited="true" ctrlrange="-42 42"/>
    <motor name="left_ankle_roll" gear="1" joint="left_ankle_roll_joint" ctrllimited="true" ctrlrange="-42 42"/>
    <!-- Right leg -->
    <motor name="right_hip_pitch" gear="1" joint="right_hip_pitch_joint" ctrllimited="true" ctrlrange="-140 140"/>
    <motor name="right_hip_roll" gear="1" joint="right_hip_roll_joint" ctrllimited="true" ctrlrange="-140 140"/>
    <motor name="right_hip_yaw" gear="1" joint="right_hip_yaw_joint" ctrllimited="true" ctrlrange="-140 140"/>
    <motor name="right_knee" gear="1" joint="right_knee_joint" ctrllimited="true" ctrlrange="-140 140"/>
    <motor name="right_ankle_pitch" gear="1" joint="right_ankle_pitch_joint" ctrllimited="true" ctrlrange="-42 42"/>
    <motor name="right_ankle_roll" gear="1" joint="right_ankle_roll_joint" ctrllimited="true" ctrlrange="-42 42"/>
    <!-- Waist -->
    <motor name="waist_yaw" gear="1" joint="waist_yaw_joint" ctrllimited="true" ctrlrange="-42 42"/>
    <motor name="waist_roll" gear="1" joint="waist_roll_joint" ctrllimited="true" ctrlrange="-42 42"/>
    <motor name="waist_pitch" gear="1" joint="waist_pitch_joint" ctrllimited="true" ctrlrange="-42 42"/>
    <!-- Head -->
    <motor name="head_yaw" gear="1" joint="head_yaw_joint" ctrllimited="true" ctrlrange="-19 19"/>
    <motor name="head_pitch" gear="1" joint="head_pitch_joint" ctrllimited="true" ctrlrange="-19 19"/>
    <!-- Left arm -->
    <motor name="left_shoulder_pitch" gear="1" joint="left_shoulder_pitch_joint" ctrllimited="true" ctrlrange="-42 42"/>
    <motor name="left_shoulder_roll" gear="1" joint="left_shoulder_roll_joint" ctrllimited="true" ctrlrange="-42 42"/>
    <motor name="left_shoulder_yaw" gear="1" joint="left_shoulder_yaw_joint" ctrllimited="true" ctrlrange="-42 42"/>
    <motor name="left_elbow" gear="1" joint="left_elbow_joint" ctrllimited="true" ctrlrange="-42 42"/>
    <motor name="left_wrist_yaw" gear="1" joint="left_wrist_yaw_joint" ctrllimited="true" ctrlrange="-19 19"/>
    <motor name="left_wrist_pitch" gear="1" joint="left_wrist_pitch_joint" ctrllimited="true" ctrlrange="-19 19"/>
    <motor name="left_wrist_roll" gear="1" joint="left_wrist_roll_joint" ctrllimited="true" ctrlrange="-19 19"/>
    <!-- Right arm -->
    <motor name="right_shoulder_pitch" gear="1" joint="right_shoulder_pitch_joint" ctrllimited="true" ctrlrange="-42 42"/>
    <motor name="right_shoulder_roll" gear="1" joint="right_shoulder_roll_joint" ctrllimited="true" ctrlrange="-42 42"/>
    <motor name="right_shoulder_yaw" gear="1" joint="right_shoulder_yaw_joint" ctrllimited="true" ctrlrange="-42 42"/>
    <motor name="right_elbow" gear="1" joint="right_elbow_joint" ctrllimited="true" ctrlrange="-42 42"/>
    <motor name="right_wrist_yaw" gear="1" joint="right_wrist_yaw_joint" ctrllimited="true" ctrlrange="-19 19"/>
    <motor name="right_wrist_pitch" gear="1" joint="right_wrist_pitch_joint" ctrllimited="true" ctrlrange="-19 19"/>
    <motor name="right_wrist_roll" gear="1" joint="right_wrist_roll_joint" ctrllimited="true" ctrlrange="-19 19"/>
  </actuator>
</mujoco>
